ERROR:app:2021-10-19 00:54:43,149, Exception on /metrics [GET]
Traceback (most recent call last):
  File "C:\Users\home\anaconda3\lib\site-packages\flask\app.py", line 2446, in wsgi_app
    response = self.full_dispatch_request()
  File "C:\Users\home\anaconda3\lib\site-packages\flask\app.py", line 1951, in full_dispatch_request
    rv = self.handle_user_exception(e)
  File "C:\Users\home\anaconda3\lib\site-packages\flask\app.py", line 1820, in handle_user_exception
    reraise(exc_type, exc_value, tb)
  File "C:\Users\home\anaconda3\lib\site-packages\flask\_compat.py", line 39, in reraise
    raise value
  File "C:\Users\home\anaconda3\lib\site-packages\flask\app.py", line 1949, in full_dispatch_request
    rv = self.dispatch_request()
  File "C:\Users\home\anaconda3\lib\site-packages\flask\app.py", line 1935, in dispatch_request
    return self.view_functions[rule.endpoint](**req.view_args)
  File ".\app.py", line 154, in metrics
    connection = get_db_connection()
  File ".\app.py", line 45, in get_db_connection
    connection.execute('SELECT * FROM posts').fetchall()
sqlite3.OperationalError: no such table: posts
WARNING:app:2021-10-19 00:54:45,697, Unhealthy
ERROR:app:2021-10-19 00:54:47,015, Exception on /metrics [GET]
Traceback (most recent call last):
  File "C:\Users\home\anaconda3\lib\site-packages\flask\app.py", line 2446, in wsgi_app
    response = self.full_dispatch_request()
  File "C:\Users\home\anaconda3\lib\site-packages\flask\app.py", line 1951, in full_dispatch_request
    rv = self.handle_user_exception(e)
  File "C:\Users\home\anaconda3\lib\site-packages\flask\app.py", line 1820, in handle_user_exception
    reraise(exc_type, exc_value, tb)
  File "C:\Users\home\anaconda3\lib\site-packages\flask\_compat.py", line 39, in reraise
    raise value
  File "C:\Users\home\anaconda3\lib\site-packages\flask\app.py", line 1949, in full_dispatch_request
    rv = self.dispatch_request()
  File "C:\Users\home\anaconda3\lib\site-packages\flask\app.py", line 1935, in dispatch_request
    return self.view_functions[rule.endpoint](**req.view_args)
  File ".\app.py", line 154, in metrics
    connection = get_db_connection()
  File ".\app.py", line 45, in get_db_connection
    connection.execute('SELECT * FROM posts').fetchall()
sqlite3.OperationalError: no such table: posts
CRITICAL:app:2021-10-19 00:55:28,087, Database not found.
ERROR:app:2021-10-19 00:55:28,088, Exception on /metrics [GET]
Traceback (most recent call last):
  File "C:\Users\home\anaconda3\lib\site-packages\flask\app.py", line 2446, in wsgi_app
    response = self.full_dispatch_request()
  File "C:\Users\home\anaconda3\lib\site-packages\flask\app.py", line 1951, in full_dispatch_request
    rv = self.handle_user_exception(e)
  File "C:\Users\home\anaconda3\lib\site-packages\flask\app.py", line 1820, in handle_user_exception
    reraise(exc_type, exc_value, tb)
  File "C:\Users\home\anaconda3\lib\site-packages\flask\_compat.py", line 39, in reraise
    raise value
  File "C:\Users\home\anaconda3\lib\site-packages\flask\app.py", line 1949, in full_dispatch_request
    rv = self.dispatch_request()
  File "C:\Users\home\anaconda3\lib\site-packages\flask\app.py", line 1935, in dispatch_request
    return self.view_functions[rule.endpoint](**req.view_args)
  File ".\app.py", line 155, in metrics
    posts=connection.execute('SELECT count(id) FROM posts').fetchall()[0][0]
AttributeError: 'NoneType' object has no attribute 'execute'
CRITICAL:app:2021-10-19 00:56:35,208, Database not found.
ERROR:app:2021-10-19 00:56:35,209, Exception on /metrics [GET]
Traceback (most recent call last):
  File "C:\Users\home\anaconda3\lib\site-packages\flask\app.py", line 2446, in wsgi_app
    response = self.full_dispatch_request()
  File "C:\Users\home\anaconda3\lib\site-packages\flask\app.py", line 1951, in full_dispatch_request
    rv = self.handle_user_exception(e)
  File "C:\Users\home\anaconda3\lib\site-packages\flask\app.py", line 1820, in handle_user_exception
    reraise(exc_type, exc_value, tb)
  File "C:\Users\home\anaconda3\lib\site-packages\flask\_compat.py", line 39, in reraise
    raise value
  File "C:\Users\home\anaconda3\lib\site-packages\flask\app.py", line 1949, in full_dispatch_request
    rv = self.dispatch_request()
  File "C:\Users\home\anaconda3\lib\site-packages\flask\app.py", line 1935, in dispatch_request
    return self.view_functions[rule.endpoint](**req.view_args)
  File ".\app.py", line 156, in metrics
    posts=connection.execute('SELECT count(id) FROM posts').fetchall()[0][0]
AttributeError: 'NoneType' object has no attribute 'execute'
CRITICAL:app:2021-10-19 00:57:26,662, Post table not found.
ERROR:app:2021-10-19 00:57:26,664, Exception on /metrics [GET]
Traceback (most recent call last):
  File "C:\Users\home\anaconda3\lib\site-packages\flask\app.py", line 2446, in wsgi_app
    response = self.full_dispatch_request()
  File "C:\Users\home\anaconda3\lib\site-packages\flask\app.py", line 1951, in full_dispatch_request
    rv = self.handle_user_exception(e)
  File "C:\Users\home\anaconda3\lib\site-packages\flask\app.py", line 1820, in handle_user_exception
    reraise(exc_type, exc_value, tb)
  File "C:\Users\home\anaconda3\lib\site-packages\flask\_compat.py", line 39, in reraise
    raise value
  File "C:\Users\home\anaconda3\lib\site-packages\flask\app.py", line 1949, in full_dispatch_request
    rv = self.dispatch_request()
  File "C:\Users\home\anaconda3\lib\site-packages\flask\app.py", line 1935, in dispatch_request
    return self.view_functions[rule.endpoint](**req.view_args)
  File ".\app.py", line 157, in metrics
    posts=connection.execute('SELECT count(id) FROM posts').fetchall()[0][0]
AttributeError: 'NoneType' object has no attribute 'execute'
CRITICAL:app:2021-10-19 00:58:31,094, Post table not found.
INFO:app:2021-10-19 00:58:31,235, Post table created.
INFO:app:2021-10-19 00:58:31,237, Accesing metrics
INFO:app:2021-10-19 00:58:49,572, Post table created.
WARNING:app:2021-10-19 00:58:49,574, Unhealthy
